Workbook

Sheet Data_Dictionary
A1: Column | B1: Meaning
A2: Record_ID | B2: Unique production run ID
A3: Production_Date | B3: Date of the run (Sunday runs are overtime runs)
A4: Month | B4: Month-Year of the run
A5: Day_of_Week | B5: Weekday name
A6: Shift | B6: A = 06:00-14:00, B = 14:00-22:00, C = 22:00-06:00
A7: Line_ID | B7: Production line code (L1-L4)
A8: Line_Name | B8: Production line name
A9: Product_Category | B9: Product family made on the line
A10: SKU_Code | B10: SKU code
A11: SKU_Name | B11: SKU description
A12: Batch_No | B12: Batch number (date + line + shift)
... A30: Note | B30: All data is synthetic and created for practice. Company, plant and supplier names are illustrative and do not represent real operations.

Sheet Data
A1: Record_ID | B1: Production_Date | C1: Month | D1: Month_No. | E1: Day_of_Week | F1: Shift | G1: Line_ID | H1: Line_Name | I1: Product_Category | J1: SKU_Code | K1: SKU_Name | L1: Batch_No | M1: Supervisor | N1: Packaging_Supplier | O1: Manpower_Planned | P1: Manpower_Present | Q1: Planned_Qty | R1: Produced_Qty | S1: Rejected_Qty | T1: Rejection% | U1: Plan_Achievement % | V1: Defect_Type | W1: Downtime_Min | X1: Downtime_Hour | Y1: Downtime_Reason | Z1: Unit_Cost_INR | AA1: Rejection_Loss_INR | AB1: Opening_FG_Stock | AC1: Demand_Qty | AD1: Dispatched_Qty | AE1: Closing_FG_Stock | AF1: Reorder_Level
A2: PR-1722 | B2: 46270 | C2: Sep-2026 | D2: =MONTH(ProductionData[[#This Row],[Month]]) -> 9 | E2: Saturday | F2: A | G2: L2 | H2: Mouthwash Bottling | I2: Mouthwash | J2: MW-MT-250 | K2: Mint Mouthwash 250ml | L2: B260905-L2A | M2: K. Verma | N2: PackRight Industries | O2: 16 | P2: 16 | Q2: 7560 | R2: 7340 | S2: 656 | T2: =(ProductionData[[#This Row],[Rejected_Qty]])/ProductionData[[#This Row],[Produced_Qty]] -> 0.089373297 | U2: =ProductionData[[#This Row],[Produced_Qty]]/ProductionData[[#This Row],[Planned_Qty]] -> 0.97089947 | V2: Underfill | W2: 55 | X2: =W2/60 -> 0.91666667 | Y2: Machine Breakdown | Z2: 46 | AA2: =ProductionData[[#This Row],[Rejected_Qty]]*ProductionData[[#This Row],[Unit_Cost_INR]] -> 30176 | AB2: 265 | AC2: 7200 | AD2: 6949 | AE2: 0 | AF2: 10500
A3: PR-0238 | B3: 46134 | C3: Apr-2026 | D3: =MONTH(ProductionData[[#This Row],[Month]]) -> 4 | E3: Wednesday | F3: B | G3: L4 | H3: Toothbrush Assembly | I3: Toothbrush | J3: TB-SF-01 | K3: Soft Toothbrush | L3: B260422-L4B | M3: S. Yadav | N3: Sunrise Packaging | O3: 18 | P3: 18 | Q3: 9710 | R3: 9480 | S3: 250 | T3: =(ProductionData[[#This Row],[Rejected_Qty]])/ProductionData[[#This Row],[Produced_Qty]] -> 0.026371308 | U3: =ProductionData[[#This Row],[Produced_Qty]]/ProductionData[[#This Row],[Planned_Qty]] -> 0.97631308 | V3: Labeling Defect | W3: 0 | X3: =W3/60 -> 0 | Y3: None | Z3: 18 | AA3: =ProductionData[[#This Row],[Rejected_Qty]]*ProductionData[[#This Row],[Unit_Cost_INR]] -> 4500 | AB3: 32540 | AC3: 9120 | AD3: 9120 | AE3: 32650 | AF3: 15000
A4: PR-0230 | B4: 46133 | C4: Apr-2026 | D4: =MONTH(ProductionData[[#This Row],[Month]]) -> 4 | E4: Tuesday | F4: C | G4: L4 | H4: Toothbrush Assembly | I4: Toothbrush | J4: TB-SF-01 | K4: Soft Toothbrush | L4: B260421-L4C | M4: M. Khan | N4: Delhi Poly Pack | O4: 18 | P4: 16 | Q4: 8780 | R4: 8540 | S4: 202 | T4: =(ProductionData[[#This Row],[Rejected_Qty]])/ProductionData[[#This Row],[Produced_Qty]] -> 0.023653396 | U4: =ProductionData[[#This Row],[Produced_Qty]]/ProductionData[[#This Row],[Planned_Qty]] -> 0.97266515 | V4: Labeling Defect | W4: 0 | X4: =W4/60 -> 0 | Y4: None | Z4: 18 | AA4: =ProductionData[[#This Row],[Rejected_Qty]]*ProductionData[[#This Row],[Unit_Cost_INR]] -> 3636 | AB4: 32242 | AC4: 8040 | AD4: 8040 | AE4: 32540 | AF4: 15000
A5: PR-0308 | B5: 46141 | C5: Apr-2026 | D5: =MONTH(ProductionData[[#This Row],[Month]]) -> 4 | E5: Wednesday | F5: A | G5: L4 | H5: Toothbrush Assembly | I5: Toothbrush | J5: TB-SF-01 | K5: Soft Toothbrush | L5: B260429-L4A | M5: R. Sharma | N5: Sunrise Packaging | O5: 18 | P5: 16 | Q5: 10000 | R5: 9400 | S5: 203 | T5: =(ProductionData[[#This Row],[Rejected_Qty]])/ProductionData[[#This Row],[Produced_Qty]] -> 0.021595745 | U5: =ProductionData[[#This Row],[Produced_Qty]]/ProductionData[[#This Row],[Planned_Qty]] -> 0.94 | V5: Underfill | W5: 65 | X5: =W5/60 -> 1.0833333 | Y5: Machine Breakdown | Z5: 18 | AA5: =ProductionData[[#This Row],[Rejected_Qty]]*ProductionData[[#This Row],[Unit_Cost_INR]] -> 3654 | AB5: 31487 | AC5: 8240 | AD5: 8240 | AE5: 32444 | AF5: 15000
A6: PR-0044 | B6: 46116 | C6: Apr-2026 | D6: =MONTH(ProductionData[[#This Row],[Month]]) -> 4 | E6: Saturday | F6: B | G6: L4 | H6: Toothbrush Assembly | I6: Toothbrush | J6: TB-SF-01 | K6: Soft Toothbrush | L6: B260404-L4B | M6: P. Singh | N6: Delhi Poly Pack | O6: 18 | P6: 16 | Q6: 10050 | R6: 9610 | S6: 195 | T6: =(ProductionData[[#This Row],[Rejected_Qty]])/ProductionData[[#This Row],[Produced_Qty]] -> 0.020291363 | U6: =ProductionData[[#This Row],[Produced_Qty]]/ProductionData[[#This Row],[Planned_Qty]] -> 0.95621891 | V6: Damaged Packaging | W6: 0 | X6: =W6/60 -> 0 | Y6: None | Z6: 18 | AA6: =ProductionData[[#This Row],[Rejected_Qty]]*ProductionData[[#This Row],[Unit_Cost_INR]] -> 3510 | AB6: 31433 | AC6: 8520 | AD6: 8520 | AE6: 32328 | AF6: 15000
A7: PR-0226 | B7: 46133 | C7: Apr-2026 | D7: =MONTH(ProductionData[[#This Row],[Month]]) -> 4 | E7: Tuesday | F7: B | G7: L4 | H7: Toothbrush Assembly | I7: Toothbrush | J7: TB-SF-01 | K7: Soft Toothbrush | L7: B260421-L4B | M7: S. Yadav | N7: Delhi Poly Pack | O7: 18 | P7: 17 | Q7: 9390 | R7: 9130 | S7: 202 | T7: =(ProductionData[[#This Row],[Rejected_Qty]])/ProductionData[[#This Row],[Produced_Qty]] -> 0.022124863 | U7: =ProductionData[[#This Row],[Produced_Qty]]/ProductionData[[#This Row],[Planned_Qty]] -> 0.97231097 | V7: Labeling Defect | W7: 0 | X7: =W7/60 -> 0 | Y7: None | Z7: 18 | AA7: =ProductionData[[#This Row],[Rejected_Qty]]*ProductionData[[#This Row],[Unit_Cost_INR]] -> 3636 | AB7: 31804 | AC7: 8490 | AD7: 8490 | AE7: 32242 | AF7: 15000
A8: PR-0246 | B8: 46135 | C8: Apr-2026 | D8: =MONTH(ProductionData[[#This Row],[Month]]) -> 4 | E8: Thursday | F8: A | G8: L4 | H8: Toothbrush Assembly | I8: Toothbrush | J8: TB-SF-01 | K8: Soft Toothbrush | L8: B260423-L4A | M8: R. Sharma | N8: Sunrise Packaging | O8: 18 | P8: 18 | Q8: 10670 | R8: 10150 | S8: 172 | T8: =(ProductionData[[#This Row],[Rejected_Qty]])/ProductionData[[#This Row],[Produced_Qty]] -> 0.016945813 | U8: =ProductionData[[#This Row],[Produced_Qty]]/ProductionData[[#This Row],[Planned_Qty]] -> 0.95126523 | V8: Seal Defect (minor) | W8: 70 | X8: =W8/60 -> 1.1666667 | Y8: Changeover | Z8: 18 | AA8: =ProductionData[[#This Row],[Rejected_Qty]]*ProductionData[[#This Row],[Unit_Cost_INR]] -> 3096 | AB8: 32650 | AC8: 10570 | AD8: 10570 | AE8: 32058 | AF8: 15000
A9: PR-0222 | B9: 46133 | C9: Apr-2026 | D9: =MONTH(ProductionData[[#This Row],[Month]]) -> 4 | E9: Tuesday | F9: A | G9: L4 | H9: Toothbrush Assembly | I9: Toothbrush | J9: TB-SF-01 | K9: Soft Toothbrush | L9: B260421-L4A | M9: K. Verma | N9: Delhi Poly Pack | O9: 18 | P9: 18 | Q9: 9670 | R9: 9470 | S9: 199 | T9: =(ProductionData[[#This Row],[Rejected_Qty]])/ProductionData[[#This Row],[Produced_Qty]] -> 0.021013728 | U9: =ProductionData[[#This Row],[Produced_Qty]]/ProductionData[[#This Row],[Planned_Qty]] -> 0.97931748 | V9: Printing Misalignment | W9: 37 | X9: =W9/60 -> 0.61666667 | Y9: Power Interruption | Z9: 18 | AA9: =ProductionData[[#This Row],[Rejected_Qty]]*ProductionData[[#This Row],[Unit_Cost_INR]] -> 3582 | AB9: 31353 | AC9: 8820 | AD9: 8820 | AE9: 31804 | AF9: 15000
A10: PR-0137 | B10: 46125 | C10: Apr-2026 | D10: =MONTH(ProductionData[[#This Row],[Month]]) -> 4 | E10: Monday | F10: B | G10: L4 | H10: Toothbrush Assembly | I10: Toothbrush | J10: TB-SF-01 | K10: Soft Toothbrush | L10: B260413-L4B | M10: S. Yadav | N10: Delhi Poly Pack | O10: 18 | P10: 17 | Q10: 10720 | R10: 10140 | S10: 280 | T10: =(ProductionData[[#This Row],[Rejected_Qty]])/ProductionData[[#This Row],[Produced_Qty]] -> 0.027613412 | U10: =ProductionData[[#This Row],[Produced_Qty]]/ProductionData[[#This Row],[Planned_Qty]] -> 0.94589552 | V10: Labeling Defect | W10: 0 | X10: =W10/60 -> 0 | Y10: None | Z10: 18 | AA10: =ProductionData[[#This Row],[Rejected_Qty]]*ProductionData[[#This Row],[Unit_Cost_INR]] -> 5040 | AB10: 30888 | AC10: 8970 | AD10: 8970 | AE10: 31778 | AF10: 15000
A11: PR-0320 | B11: 46142 | C11: Apr-2026 | D11: =MONTH(ProductionData[[#This Row],[Month]]) -> 4 | E11: Thursday | F11: A | G11: L4 | H11: Toothbrush Assembly | I11: Toothbrush | J11: TB-SF-01 | K11: Soft Toothbrush | L11: B260430-L4A | M11: R. Sharma | N11: Sunrise Packaging | O11: 18 | P11: 17 | Q11: 9870 | R11: 10090 | S11: 308 | T11: =(ProductionData[[#This Row],[Rejected_Qty]])/ProductionData[[#This Row],[Produced_Qty]] -> 0.030525273 | U11: =ProductionData[[#This Row],[Produced_Qty]]/ProductionData[[#This Row],[Planned_Qty]] -> 1.0222898 | V11: Underfill | W11: 19 | X11: =W11/60 -> 0.31666667 | Y11: Changeover | Z11: 18 | AA11: =ProductionData[[#This Row],[Rejected_Qty]]*ProductionData[[#This Row],[Unit_Cost_INR]] -> 5544 | AB11: 31405 | AC11: 9480 | AD11: 9480 | AE11: 31707 | AF11: 15000
A12: PR-0254 | B12: 46135 | C12: Apr-2026 | D12: =MONTH(ProductionData[[#This Row],[Month]]) -> 4 | E12: Thursday | F12: C | G12: L4 | H12: Toothbrush Assembly | I12: Toothbrush | J12: TB-SF-01 | K12: Soft Toothbrush | L12: B260423-L4C | M12: M. Khan | N12: Sunrise Packaging | O12: 18 | P12: 17 | Q12: 9720 | R12: 8540 | S12: 133 | T12: =(ProductionData[[#This Row],[Rejected_Qty]])/ProductionData[[#This Row],[Produced_Qty]] -> 0.01557377 | U12: =ProductionData[[#This Row],[Produced_Qty]]/ProductionData[[#This Row],[Planned_Qty]] -> 0.87860082 | V12: Seal Defect (minor) | W12: 41 | X12: =W12/60 -> 0.68333333 | Y12: Changeover | Z12: 18 | AA12: =ProductionData[[#This Row],[Rejected_Qty]]*ProductionData[[#This Row],[Unit_Cost_INR]] -> 2394 | AB12: 32058 | AC12: 8780 | AD12: 8780 | AE12: 31685 | AF12: 15000
A13: PR-0288 | B13: 46139 | C13: Apr-2026 | D13: =MONTH(ProductionData[[#This Row],[Month]]) -> 4 | E13: Monday | F13: B | G13: L4 | H13: Toothbrush Assembly | I13: Toothbrush | J13: TB-SF-01 | K13: Soft Toothbrush | L13: B260427-L4B | M13: P. Singh | N13: Delhi Poly Pack | O13: 18 | P13: 18 | Q13: 9850 | R13: 9760 | S13: 295 | T13: =(ProductionData[[#This Row],[Rejected_Qty]])/ProductionData[[#This Row],[Produced_Qty]] -> 0.03022541 | U13: =ProductionData[[#This Row],[Produced_Qty]]/ProductionData[[#This Row],[Planned_Qty]] -> 0.99086294 | V13: Seal Defect (minor) | W13: 49 | X13: =W13/60 -> 0.81666667 | Y13: Machine Breakdown | Z13: 18 | AA13: =ProductionData[[#This Row],[Rejected_Qty]]*ProductionData[[#This Row],[Unit_Cost_INR]] -> 5310 | AB13: 31172 | AC13: 9150 | AD13: 9150 | AE13: 31487 | AF13: 15000
... A228: PR-0079 | B228: 46120 | C228: Apr-2026 | D228: =MONTH(ProductionData[[#This Row],[Month]]) -> 4 | E228: Wednesday | F228: A | G228: L2 | H228: Mouthwash Bottling | I228: Mouthwash | J228: MW-AF-250 | K228: Alcohol-Free Mouthwash 250ml | L228: B260408-L2A | M228: K. Verma | N228: Delhi Poly Pack | O228: 16 | P228: 12 | Q228: 5980 | R228: 5130 | S228: 95 | T228: =(ProductionData[[#This Row],[Rejected_Qty]])/ProductionData[[#This Row],[Produced_Qty]] -> 0.018518519 | U228: =ProductionData[[#This Row],[Produced_Qty]]/ProductionData[[#This Row],[Planned_Qty]] -> 0.85785953 | V228: Underfill | W228: 0 | X228: =W228/60 -> 0 | Y228: None | Z228: 58 | AA228: =ProductionData[[#This Row],[Rejected_Qty]]*ProductionData[[#This Row],[Unit_Cost_INR]] -> 5510 | AB228: 19666 | AC228: 6080 | AD228: 6080 | AE228: 18621 | AF228: 9000
A229: {=SUMPRODUCT(Data!AE2:AE2001 <> Data!AB2:AB2001 + Data!R2:R2001 -Data!S2:S2001 -Data!AD1966:AD1971)} -> #N/A | B229: 46114 | C229: Apr-2026 | D229: =MONTH(ProductionData[[#This Row],[Month]]) -> 4 | E229: Thursday | F229: A | G229: L2 | H229: Mouthwash Bottling | I229: Mouthwash | J229: MW-AF-250 | K229: Alcohol-Free Mouthwash 250ml | L229: B260402-L2A | M229: K. Verma | N229: Delhi Poly Pack | O229: 16 | P229: 16 | Q229: 5990 | R229: 5830 | S229: 138 | T229: =(ProductionData[[#This Row],[Rejected_Qty]])/ProductionData[[#This Row],[Produced_Qty]] -> 0.023670669 | U229: =ProductionData[[#This Row],[Produced_Qty]]/ProductionData[[#This Row],[Planned_Qty]] -> 0.97328881 | V229: Underfill | W229: 56 | X229: =W229/60 -> 0.93333333 | Y229: Power Interruption | Z229: 58 | AA229: =ProductionData[[#This Row],[Rejected_Qty]]*ProductionData[[#This Row],[Unit_Cost_INR]] -> 8004 | AB229: 18000 | AC229: 5160 | AD229: 5160 | AE229: 18532 | AF229: 9000
A230: PR-0087 | B230: 46120 | C230: Apr-2026 | D230: =MONTH(ProductionData[[#This Row],[Month]]) -> 4 | E230: Wednesday | F230: C | G230: L2 | H230: Mouthwash Bottling | I230: Mouthwash | J230: MW-AF-250 | K230: Alcohol-Free Mouthwash 250ml | L230: B260408-L2C | M230: A. Gupta | N230: Delhi Poly Pack | O230: 16 | P230: 16 | Q230: 5820 | R230: 5280 | S230: 133 | T230: =(ProductionData[[#This Row],[Rejected_Qty]])/ProductionData[[#This Row],[Produced_Qty]] -> 0.025189394 | U230: =ProductionData[[#This Row],[Produced_Qty]]/ProductionData[[#This Row],[Planned_Qty]] -> 0.90721649 | V230: Damaged Packaging | W230: 0 | X230: =W230/60 -> 0 | Y230: None | Z230: 58 | AA230: =ProductionData[[#This Row],[Rejected_Qty]]*ProductionData[[#This Row],[Unit_Cost_INR]] -> 7714 | AB230: 18638 | AC230: 5410 | AD230: 5410 | AE230: 18375 | AF230: 9000
A231: PR-0119 | B231: 46123 | C231: Apr-2026 | D231: =MONTH(ProductionData[[#This Row],[Month]]) -> 4 | E231: Saturday | F231: B | G231: L2 | H231: Mouthwash Bottling | I231: Mouthwash | J231: MW-AF-250 | K231: Alcohol-Free Mouthwash 250ml | L231: B260411-L2B | M231: P. Singh | N231: Delhi Poly Pack | O231: 16 | P231: 15 | Q231: 6160 | R231: 5640 | S231: 96 | T231: =(ProductionData[[#This Row],[Rejected_Qty]])/ProductionData[[#This Row],[Produced_Qty]] -> 0.017021277 | U231: =ProductionData[[#This Row],[Produced_Qty]]/ProductionData[[#This Row],[Planned_Qty]] -> 0.91558442 | V231: Damaged Packaging | W231: 0 | X231: =W231/60 -> 0 | Y231: None | Z231: 58 | AA231: =ProductionData[[#This Row],[Rejected_Qty]]*ProductionData[[#This Row],[Unit_Cost_INR]] -> 5568 | AB231: 18071 | AC231: 5260 | AD231: 5260 | AE231: 18355 | AF231: 9000
A232: PR-0091 | B232: 46121 | C232: Apr-2026 | D232: =MONTH(ProductionData[[#This Row],[Month]]) -> 4 | E232: Thursday | F232: A | G232: L2 | H232: Mouthwash Bottling | I232: Mouthwash | J232: MW-AF-250 | K232: Alcohol-Free Mouthwash 250ml | L232: B260409-L2A | M232: K. Verma | N232: Sunrise Packaging | O232: 16 | P232: 15 | Q232: 5890 | R232: 5180 | S232: 174 | T232: =(ProductionData[[#This Row],[Rejected_Qty]])/ProductionData[[#This Row],[Produced_Qty]] -> 0.033590734 | U232: =ProductionData[[#This Row],[Produced_Qty]]/ProductionData[[#This Row],[Planned_Qty]] -> 0.87945671 | V232: Seal Defect (minor) | W232: 0 | X232: =W232/60 -> 0 | Y232: None | Z232: 58 | AA232: =ProductionData[[#This Row],[Rejected_Qty]]*ProductionData[[#This Row],[Unit_Cost_INR]] -> 10092 | AB232: 18375 | AC232: 5310 | AD232: 5310 | AE232: 18071 | AF232: 9000
A233: PR-0009 | B233: 46113 | C233: Apr-2026 | D233: =MONTH(ProductionData[[#This Row],[Month]]) -> 4 | E233: Wednesday | F233: C | G233: L1 | H233: Toothpaste Tube Filling | I233: Toothpaste | J233: TP-CH-150 | K233: Charcoal Toothpaste 150g | L233: B260401-L1C | M233: A. Gupta | N233: Delhi Poly Pack | O233: 14 | P233: 12 | Q233: 6140 | R233: 5770 | S233: 170 | T233: =(ProductionData[[#This Row],[Rejected_Qty]])/ProductionData[[#This Row],[Produced_Qty]] -> 0.029462738 | U233: =ProductionData[[#This Row],[Produced_Qty]]/ProductionData[[#This Row],[Planned_Qty]] -> 0.93973941 | V233: Underfill | W233: 0 | X233: =W233/60 -> 0 | Y233: None | Z233: 51 | AA233: =ProductionData[[#This Row],[Rejected_Qty]]*ProductionData[[#This Row],[Unit_Cost_INR]] -> 8670 | AB233: 18000 | AC233: 5950 | AD233: 5950 | AE233: 17650 | AF233: 9000
A234: {=COUNTA(Data!S2:S2001 >Data!R2:R2001)} -> 2000 | B234: 46114 | C234: Apr-2026 | D234: =MONTH(ProductionData[[#This Row],[Month]]) -> 4 | E234: Thursday | F234: B | G234: L1 | H234: Toothpaste Tube Filling | I234: Toothpaste | J234: TP-CH-150 | K234: Charcoal Toothpaste 150g | L234: B260402-L1B | M234: P. Singh | N234: Sunrise Packaging | O234: 14 | P234: 13 | Q234: 6060 | R234: 5660 | S234: 156 | T234: =(ProductionData[[#This Row],[Rejected_Qty]])/ProductionData[[#This Row],[Produced_Qty]] -> 0.027561837 | U234: =ProductionData[[#This Row],[Produced_Qty]]/ProductionData[[#This Row],[Planned_Qty]] -> 0.9339934 | V234: Seal Defect (minor) | W234: 0 | X234: =W234/60 -> 0 | Y234: None | Z234: 51 | AA234: =ProductionData[[#This Row],[Rejected_Qty]]*ProductionData[[#This Row],[Unit_Cost_INR]] -> 7956 | AB234: 17650 | AC234: 5820 | AD234: 5820 | AE234: 17334 | AF234: 9000
A235: PR-0029 | B235: 46115 | C235: Apr-2026 | D235: =MONTH(ProductionData[[#This Row],[Month]]) -> 4 | E235: Friday | F235: B | G235: L1 | H235: Toothpaste Tube Filling | I235: Toothpaste | J235: TP-CH-150 | K235: Charcoal Toothpaste 150g | L235: B260403-L1B | M235: P. Singh | N235: Sunrise Packaging | O235: 14 | P235: 14 | Q235: 6270 | R235: 6240 | S235: 109 | T235: =(ProductionData[[#This Row],[Rejected_Qty]])/ProductionData[[#This Row],[Produced_Qty]] -> 0.017467949 | U235: =ProductionData[[#This Row],[Produced_Qty]]/ProductionData[[#This Row],[Planned_Qty]] -> 0.99521531 | V235: Seal Defect (minor) | W235: 0 | X235: =W235/60 -> 0 | Y235: None | Z235: 51 | AA235: =ProductionData[[#This Row],[Rejected_Qty]]*ProductionData[[#This Row],[Unit_Cost_INR]] -> 5559 | AB235: 17334 | AC235: 6190 | AD235: 6190 | AE235: 17275 | AF235: 9000
A236: PR-0118 | B236: 46123 | C236: Apr-2026 | D236: =MONTH(ProductionData[[#This Row],[Month]]) -> 4 | E236: Saturday | F236: B | G236: L1 | H236: Toothpaste Tube Filling | I236: Toothpaste | J236: TP-CH-150 | K236: Charcoal Toothpaste 150g | L236: B260411-L1B | M236: S. Yadav | N236: Delhi Poly Pack | O236: 14 | P236: 14 | Q236: 6180 | R236: 5800 | S236: 86 | T236: =(ProductionData[[#This Row],[Rejected_Qty]])/ProductionData[[#This Row],[Produced_Qty]] -> 0.014827586 | U236: =ProductionData[[#This Row],[Produced_Qty]]/ProductionData[[#This Row],[Planned_Qty]] -> 0.93851133 | V236: Damaged Packaging | W236: 0 | X236: =W236/60 -> 0 | Y236: None | Z236: 51 | AA236: =ProductionData[[#This Row],[Rejected_Qty]]*ProductionData[[#This Row],[Unit_Cost_INR]] -> 4386 | AB236: 16706 | AC236: 5190 | AD236: 5190 | AE236: 17230 | AF236: 9000
A237: PR-0182 | B237: 46129 | C237: Apr-2026 | D237: =MONTH(ProductionData[[#This Row],[Month]]) -> 4 | E237: Friday | F237: B | G237: L1 | H237: Toothpaste Tube Filling | I237: Toothpaste | J237: TP-CH-150 | K237: Charcoal Toothpaste 150g | L237: B260417-L1B | M237: P. Singh | N237: Delhi Poly Pack | O237: 14 | P237: 14 | Q237: 5900 | R237: 5560 | S237: 113 | T237: =(ProductionData[[#This Row],[Rejected_Qty]])/ProductionData[[#This Row],[Produced_Qty]] -> 0.020323741 | U237: =ProductionData[[#This Row],[Produced_Qty]]/ProductionData[[#This Row],[Planned_Qty]] -> 0.94237288 | V237: Seal Defect (minor) | W237: 0 | X237: =W237/60 -> 0 | Y237: None | Z237: 51 | AA237: =ProductionData[[#This Row],[Rejected_Qty]]*ProductionData[[#This Row],[Unit_Cost_INR]] -> 5763 | AB237: 16769 | AC237: 5150 | AD237: 5150 | AE237: 17066 | AF237: 9000
A238: PR-0070 | B238: 46119 | C238: Apr-2026 | D238: =MONTH(ProductionData[[#This Row],[Month]]) -> 4 | E238: Tuesday | F238: B | G238: L1 | H238: Toothpaste Tube Filling | I238: Toothpaste | J238: TP-CH-150 | K238: Charcoal Toothpaste 150g | L238: B260407-L1B | M238: P. Singh | N238: Delhi Poly Pack | O238: 14 | P238: 12 | Q238: 5610 | R238: 5140 | S238: 48 | T238: =(ProductionData[[#This Row],[Rejected_Qty]])/ProductionData[[#This Row],[Produced_Qty]] -> 0.0093385214 | U238: =ProductionData[[#This Row],[Produced_Qty]]/ProductionData[[#This Row],[Planned_Qty]] -> 0.91622103 | V238: Printing Misalignment | W238: 0 | X238: =W238/60 -> 0 | Y238: None | Z238: 51 | AA238: =ProductionData[[#This Row],[Rejected_Qty]]*ProductionData[[#This Row],[Unit_Cost_INR]] -> 2448 | AB238: 16699 | AC238: 4750 | AD238: 4750 | AE238: 17041 | AF238: 9000
A239: PR-0037 | B239: 46116 | C239: Apr-2026 | D239: =MONTH(ProductionData[[#This Row],[Month]]) -> 4 | E239: Saturday | F239: A | G239: L1 | H239: Toothpaste Tube Filling | I239: Toothpaste | J239: TP-CH-150 | K239: Charcoal Toothpaste 150g | L239: B260404-L1A | M239: R. Sharma | N239: Sunrise Packaging | O239: 14 | P239: 12 | Q239: 5600 | R239: 5170 | S239: 149 | T239: =(ProductionData[[#This Row],[Rejected_Qty]])/ProductionData[[#This Row],[Produced_Qty]] -> 0.028820116 | U239: =ProductionData[[#This Row],[Produced_Qty]]/ProductionData[[#This Row],[Planned_Qty]] -> 0.92321429 | V239: Damaged Packaging | W239: 68 | X239: =W239/60 -> 1.1333333 | Y239: Machine Breakdown | Z239: 51 | AA239: =ProductionData[[#This Row],[Rejected_Qty]]*ProductionData[[#This Row],[Unit_Cost_INR]] -> 7599 | AB239: 17275 | AC239: 5320 | AD239: 5320 | AE239: 16976 | AF239: 9000
A240: PR-0215 | B240: 46132 | C240: Apr-2026 | D240: =MONTH(ProductionData[[#This Row],[Month]]) -> 4 | E240: Monday | F240: C | G240: L1 | H240: Toothpaste Tube Filling | I240: Toothpaste | J240: TP-CH-150 | K240: Charcoal Toothpaste 150g | L240: B260420-L1C | M240: A. Gupta | N240: Sunrise Packaging | O240: 14 | P240: 13 | Q240: 5750 | R240: 5170 | S240: 132 | T240: =(ProductionData[[#This Row],[Rejected_Qty]])/ProductionData[[#This Row],[Produced_Qty]] -> 0.025531915 | U240: =ProductionData[[#This Row],[Produced_Qty]]/ProductionData[[#This Row],[Planned_Qty]] -> 0.89913043 | V240: Underfill | W240: 34 | X240: =W240/60 -> 0.56666667 | Y240: Power Interruption | Z240: 51 | AA240: =ProductionData[[#This Row],[Rejected_Qty]]*ProductionData[[#This Row],[Unit_Cost_INR]] -> 6732 | AB240: 16673 | AC240: 4750 | AD240: 4750 | AE240: 16961 | AF240: 9000
A241: PR-0178 | B241: 46129 | C241: Apr-2026 | D241: =MONTH(ProductionData[[#This Row],[Month]]) -> 4 | E241: Friday | F241: A | G241: L1 | H241: Toothpaste Tube Filling | I241: Toothpaste | J241: TP-CH-150 | K241: Charcoal Toothpaste 150g | L241: B260417-L1A | M241: K. Verma | N241: Delhi Poly Pack | O241: 14 | P241: 14 | Q241: 5940 | R241: 5940 | S241: 138 | T241: =(ProductionData[[#This Row],[Rejected_Qty]])/ProductionData[[#This Row],[Produced_Qty]] -> 0.023232323 | U241: =ProductionData[[#This Row],[Produced_Qty]]/ProductionData[[#This Row],[Planned_Qty]] -> 1 | V241: Labeling Defect | W241: 0 | X241: =W241/60 -> 0 | Y241: None | Z241: 51 | AA241: =ProductionData[[#This Row],[Rejected_Qty]]*ProductionData[[#This Row],[Unit_Cost_INR]] -> 7038 | AB241: 16017 | AC241: 5050 | AD241: 5050 | AE241: 16769 | AF241: 9000
A242: PR-0090 | B242: 46121 | C242: Apr-2026 | D242: =MONTH(ProductionData[[#This Row],[Month]]) -> 4 | E242: Thursday | F242: A | G242: L1 | H242: Toothpaste Tube Filling | I242: Toothpaste | J242: TP-CH-150 | K242: Charcoal Toothpaste 150g | L242: B260409-L1A | M242: R. Sharma | N242: Delhi Poly Pack | O242: 14 | P242: 14 | Q242: 5720 | R242: 5820 | S242: 124 | T242: =(ProductionData[[#This Row],[Rejected_Qty]])/ProductionData[[#This Row],[Produced_Qty]] -> 0.021305842 | U242: =ProductionData[[#This Row],[Produced_Qty]]/ProductionData[[#This Row],[Planned_Qty]] -> 1.0174825 | V242: Underfill | W242: 0 | X242: =W242/60 -> 0 | Y242: None | Z242: 51 | AA242: =ProductionData[[#This Row],[Rejected_Qty]]*ProductionData[[#This Row],[Unit_Cost_INR]] -> 6324 | AB242: 15810 | AC242: 4800 | AD242: 4800 | AE242: 16706 | AF242: 9000
A243: PR-0058 | B243: 46118 | C243: Apr-2026 | D243: =MONTH(ProductionData[[#This Row],[Month]]) -> 4 | E243: Monday | F243: B | G243: L1 | H243: Toothpaste Tube Filling | I243: Toothpaste | J243: TP-CH-150 | K243: Charcoal Toothpaste 150g | L243: B260406-L1B | M243: S. Yadav | N243: Delhi Poly Pack | O243: 14 | P243: 13 | Q243: 6350 | R243: 5880 | S243: 97 | T243: =(ProductionData[[#This Row],[Rejected_Qty]])/ProductionData[[#This Row],[Produced_Qty]] -> 0.016496599 | U243: =ProductionData[[#This Row],[Produced_Qty]]/ProductionData[[#This Row],[Planned_Qty]] -> 0.92598425 | V243: Damaged Packaging | W243: 0 | X243: =W243/60 -> 0 | Y243: None | Z243: 51 | AA243: =ProductionData[[#This Row],[Rejected_Qty]]*ProductionData[[#This Row],[Unit_Cost_INR]] -> 4947 | AB243: 16976 | AC243: 6060 | AD243: 6060 | AE243: 16699 | AF243: 9000
A244: PR-0207 | B244: 46132 | C244: Apr-2026 | D244: =MONTH(ProductionData[[#This Row],[Month]]) -> 4 | E244: Monday | F244: A | G244: L1 | H244: Toothpaste Tube Filling | I244: Toothpaste | J244: TP-CH-150 | K244: Charcoal Toothpaste 150g | L244: B260420-L1A | M244: K. Verma | N244: Sunrise Packaging | O244: 14 | P244: 13 | Q244: 6180 | R244: 5630 | S244: 143 | T244: =(ProductionData[[#This Row],[Rejected_Qty]])/ProductionData[[#This Row],[Produced_Qty]] -> 0.025399645 | U244: =ProductionData[[#This Row],[Produced_Qty]]/ProductionData[[#This Row],[Planned_Qty]] -> 0.91100324 | V244: Seal Defect (minor) | W244: 31 | X244: =W244/60 -> 0.51666667 | Y244: Machine Breakdown | Z244: 51 | AA244: =ProductionData[[#This Row],[Rejected_Qty]]*ProductionData[[#This Row],[Unit_Cost_INR]] -> 7293 | AB244: 17066 | AC244: 5880 | AD244: 5880 | AE244: 16673 | AF244: 9000
A245: PR-0074 | B245: 46119 | C245: Apr-2026 | D245: =MONTH(ProductionData[[#This Row],[Month]]) -> 4 | E245: Tuesday | F245: C | G245: L1 | H245: Toothpaste Tube Filling | I245: Toothpaste | J245: TP-CH-150 | K245: Charcoal Toothpaste 150g | L245: B260407-L1C | M245: M. Khan | N245: Delhi Poly Pack | O245: 14 | P245: 11 | Q245: 5390 | R245: 4600 | S245: 179 | T245: =(ProductionData[[#This Row],[Rejected_Qty]])/ProductionData[[#This Row],[Produced_Qty]] -> 0.038913043 | U245: =ProductionData[[#This Row],[Produced_Qty]]/ProductionData[[#This Row],[Planned_Qty]] -> 0.85343228 | V245: Printing Misalignment | W245: 71 | X245: =W245/60 -> 1.1833333 | Y245: Machine Breakdown | Z245: 51 | AA245: =ProductionData[[#This Row],[Rejected_Qty]]*ProductionData[[#This Row],[Unit_Cost_INR]] -> 9129 | AB245: 17041 | AC245: 4900 | AD245: 4900 | AE245: 16562 | AF245: 9000
A246: PR-0223 | B246: 46133 | C246: Apr-2026 | D246: =MONTH(ProductionData[[#This Row],[Month]]) -> 4 | E246: Tuesday | F246: B | G246: L1 | H246: Toothpaste Tube Filling | I246: Toothpaste | J246: TP-CH-150 | K246: Charcoal Toothpaste 150g | L246: B260421-L1B | M246: P. Singh | N246: Delhi Poly Pack | O246: 14 | P246: 13 | Q246: 5670 | R246: 5140 | S246: 154 | T246: =(ProductionData[[#This Row],[Rejected_Qty]])/ProductionData[[#This Row],[Produced_Qty]] -> 0.029961089 | U246: =ProductionData[[#This Row],[Produced_Qty]]/ProductionData[[#This Row],[Planned_Qty]] -> 0.90652557 | V246: Seal Defect (minor) | W246: 64 | X246: =W246/60 -> 1.0666667 | Y246: Machine Breakdown | Z246: 51 | AA246: =ProductionData[[#This Row],[Rejected_Qty]]*ProductionData[[#This Row],[Unit_Cost_INR]] -> 7854 | AB246: 16961 | AC246: 5530 | AD246: 5530 | AE246: 16417 | AF246: 9000
... A319: PR-0016 | B319: 46114 | C319: Apr-2026 | D319: =MONTH(ProductionData[[#This Row],[Month]]) -> 4 | E319: Thursday | F319: A | G319: L4 | H319: Toothbrush Assembly | I319: Toothbrush | J319: TB-EL-01 | K319: Electric Toothbrush Head Pack | L319: B260402-L4A | M319: R. Sharma | N319: Sunrise Packaging | O319: 18 | P319: 16 | Q319: 3310 | R319: 3290 | S319: 105 | T319: =(ProductionData[[#This Row],[Rejected_Qty]])/ProductionData[[#This Row],[Produced_Qty]] -> 0.031914894 | U319: =ProductionData[[#This Row],[Produced_Qty]]/ProductionData[[#This Row],[Planned_Qty]] -> 0.9939577 | V319: Printing Misalignment | W319: 0 | X319: =W319/60 -> 0 | Y319: None | Z319: 64 | AA319: =ProductionData[[#This Row],[Rejected_Qty]]*ProductionData[[#This Row],[Unit_Cost_INR]] -> 6720 | AB319: 11559 | AC319: 3130 | AD319: 3130 | AE319: 11614 | AF319: 5250
A320: PR-0081 | B320: =SUM(IF('Data'!J2:J2001 = "MW-MT-250",('Data'!AB2:AB2001 - 'Data'!AC2:AC2001)*'Data'!Z2:Z2001) | C320: Apr-2026 | D320: =MONTH(ProductionData[[#This Row],[Month]]) -> 4 | E320: Wednesday | F320: A | G320: L4 | H320: Toothbrush Assembly | I320: Toothbrush | J320: TB-EL-01 | K320: Electric Toothbrush Head Pack | L320: B260408-L4A | M320: K. Verma | N320: Delhi Poly Pack | O320: 18 | P320: 18 | Q320: 3730 | R320: 3530 | S320: 89 | T320: =(ProductionData[[#This Row],[Rejected_Qty]])/ProductionData[[#This Row],[Produced_Qty]] -> 0.025212465 | U320: =ProductionData[[#This Row],[Produced_Qty]]/ProductionData[[#This Row],[Planned_Qty]] -> 0.9463807 | V320: Seal Defect (minor) | W320: 0 | X320: =W320/60 -> 0 | Y320: None | Z320: 64 | AA320: =ProductionData[[#This Row],[Rejected_Qty]]*ProductionData[[#This Row],[Unit_Cost_INR]] -> 5696 | AB320: 11484 | AC320: 3330 | AD320: 3330 | AE320: 11595 | AF320: 5250
A321: PR-0270 | B321: 46137 | C321: Apr-2026 | D321: =MONTH(ProductionData[[#This Row],[Month]]) -> 4 | E321: Saturday | F321: A | G321: L4 | H321: Toothbrush Assembly | I321: Toothbrush | J321: TB-EL-01 | K321: Electric Toothbrush Head Pack | L321: B260425-L4A | M321: K. Verma | N321: Delhi Poly Pack | O321: 18 | P321: 17 | Q321: 3640 | R321: 3520 | S321: 122 | T321: =(ProductionData[[#This Row],[Rejected_Qty]])/ProductionData[[#This Row],[Produced_Qty]] -> 0.034659091 | U321: =ProductionData[[#This Row],[Produced_Qty]]/ProductionData[[#This Row],[Planned_Qty]] -> 0.96703297 | V321: Underfill | W321: 12 | X321: =W321/60 -> 0.2 | Y321: Machine Breakdown | Z321: 64 | AA321: =ProductionData[[#This Row],[Rejected_Qty]]*ProductionData[[#This Row],[Unit_Cost_INR]] -> 7808 | AB321: 11401 | AC321: 3210 | AD321: 3210 | AE321: 11589 | AF321: 5250
A322: PR-0008 | B322: 46113 | C322: Apr-2026 | D322: =MONTH(ProductionData[[#This Row],[Month]]) -> 4 | E322: Wednesday | F322: B | G322: L4 | H322: Toothbrush Assembly | I322: Toothbrush | J322: TB-EL-01 | K322: Electric Toothbrush Head Pack | L322: B260401-L4B | M322: S. Yadav | N322: Delhi Poly Pack | O322: 18 | P322: 18 | Q322: 3260 | R322: 3080 | S322: 105 | T322: =(ProductionData[[#This Row],[Rejected_Qty]])/ProductionData[[#This Row],[Produced_Qty]] -> 0.034090909 | U322: =ProductionData[[#This Row],[Produced_Qty]]/ProductionData[[#This Row],[Planned_Qty]] -> 0.94478528 | V322: Seal Defect (minor) | W322: 0 | X322: =W322/60 -> 0 | Y322: None | Z322: 64 | AA322: =ProductionData[[#This Row],[Rejected_Qty]]*ProductionData[[#This Row],[Unit_Cost_INR]] -> 6720 | AB322: 11364 | AC322: 2780 | AD322: 2780 | AE322: 11559 | AF322: 5250
A323: PR-0020 | B323: 46114 | C323: Apr-2026 | D323: =MONTH(ProductionData[[#This Row],[Month]]) -> 4 | E323: Thursday | F323: B | G323: L4 | H323: Toothbrush Assembly | I323: Toothbrush | J323: TB-EL-01 | K323: Electric Toothbrush Head Pack | L323: B260402-L4B | M323: S. Yadav | N323: Delhi Poly Pack | O323: 18 | P323: 14 | Q323: 3640 | R323: 3220 | S323: 77 | T323: =(ProductionData[[#This Row],[Rejected_Qty]])/ProductionData[[#This Row],[Produced_Qty]] -> 0.023913043 | U323: =ProductionData[[#This Row],[Produced_Qty]]/ProductionData[[#This Row],[Planned_Qty]] -> 0.88461538 | V323: Labeling Defect | W323: 0 | X323: =W323/60 -> 0 | Y323: None | Z323: 64 | AA323: =ProductionData[[#This Row],[Rejected_Qty]]*ProductionData[[#This Row],[Unit_Cost_INR]] -> 4928 | AB323: 11614 | AC323: 3240 | AD323: 3240 | AE323: 11517 | AF323: 5250
A324: PR-0048 | B324: 46116 | C324: Apr-2026 | D324: =MONTH(ProductionData[[#This Row],[Month]]) -> 4 | E324: Saturday | F324: C | G324: L4 | H324: Toothbrush Assembly | I324: Toothbrush | J324: TB-EL-01 | K324: Electric Toothbrush Head Pack | L324: B260404-L4C | M324: M. Khan | N324: Delhi Poly Pack | O324: 18 | P324: 13 | Q324: 3560 | R324: 3320 | S324: 95 | T324: =(ProductionData[[#This Row],[Rejected_Qty]])/ProductionData[[#This Row],[Produced_Qty]] -> 0.028614458 | U324: =ProductionData[[#This Row],[Produced_Qty]]/ProductionData[[#This Row],[Planned_Qty]] -> 0.93258427 | V324: Damaged Packaging | W324: 15 | X324: =W324/60 -> 0.25 | Y324: Manpower Shortage | Z324: 64 | AA324: =ProductionData[[#This Row],[Rejected_Qty]]*ProductionData[[#This Row],[Unit_Cost_INR]] -> 6080 | AB324: 11517 | AC324: 3230 | AD324: 3230 | AE324: 11512 | AF324: 5250
A325: PR-0218 | B325: 46132 | C325: Apr-2026 | D325: =MONTH(ProductionData[[#This Row],[Month]]) -> 4 | E325: Monday | F325: C | G325: L4 | H325: Toothbrush Assembly | I325: Toothbrush | J325: TB-EL-01 | K325: Electric Toothbrush Head Pack | L325: B260420-L4C | M325: M. Khan | N325: Delhi Poly Pack | O325: 18 | P325: 13 | Q325: 3150 | R325: 2630 | S325: 75 | T325: =(ProductionData[[#This Row],[Rejected_Qty]])/ProductionData[[#This Row],[Produced_Qty]] -> 0.02851711 | U325: =ProductionData[[#This Row],[Produced_Qty]]/ProductionData[[#This Row],[Planned_Qty]] -> 0.83492063 | V325: Seal Defect (minor) | W325: 55 | X325: =W325/60 -> 0.91666667 | Y325: Changeover | Z325: 64 | AA325: =ProductionData[[#This Row],[Rejected_Qty]]*ProductionData[[#This Row],[Unit_Cost_INR]] -> 4800 | AB325: 11856 | AC325: 2910 | AD325: 2910 | AE325: 11501 | AF325: 5250
A326: PR-0069 | B326: 46119 | C326: Apr-2026 | D326: =MONTH(ProductionData[[#This Row],[Month]]) -> 4 | E326: Tuesday | F326: A | G326: L4 | H326: Toothbrush Assembly | I326: Toothbrush | J326: TB-EL-01 | K326: Electric Toothbrush Head Pack | L326: B260407-L4A | M326: K. Verma | N326: Sunrise Packaging | O326: 18 | P326: 18 | Q326: 3770 | R326: 3670 | S326: 96 | T326: =(ProductionData[[#This Row],[Rejected_Qty]])/ProductionData[[#This Row],[Produced_Qty]] -> 0.026158038 | U326: =ProductionData[[#This Row],[Produced_Qty]]/ProductionData[[#This Row],[Planned_Qty]] -> 0.9734748 | V326: Seal Defect (minor) | W326: 0 | X326: =W326/60 -> 0 | Y326: None | Z326: 64 | AA326: =ProductionData[[#This Row],[Rejected_Qty]]*ProductionData[[#This Row],[Unit_Cost_INR]] -> 6144 | AB326: 11410 | AC326: 3500 | AD326: 3500 | AE326: 11484 | AF326: 5250
...

Sheet Sheet1
A1: summary by month
A2: Month | B2: Sum of Planned_Qty | C2: Sum of Produced_Qty | D2: Sum of Rejected_Qty | E2: Average of Rejection% | F2: Average of Plan_Achievement % | G2: Sum of Downtime_Hour
A3: Apr-2026 | B3: 2204500 | C3: 2059110 | D3: 49199 | E3: 0.02393705 | F3: 0.93375047 | G3: 79.2
A4: May-2026 | B4: 2213150 | C4: 2066070 | D4: 53056 | E4: 0.025725994 | F4: 0.93252683 | G4: 84.916667
A5: Jun-2026 | B5: 2234830 | C5: 2096700 | D5: 52334 | E5: 0.024853198 | F5: 0.93699486 | G5: 86.216667
A6: Jul-2026 | B6: 2240760 | C6: 2088630 | D6: 70102 | E6: 0.03471363 | F6: 0.93167164 | G6: 95.316667
A7: Aug-2026 | B7: 2178630 | C7: 2042700 | D7: 66815 | E7: 0.034210622 | F7: 0.93634097 | G7: 86.35
A8: Sep-2026 | B8: 2153940 | C8: 2020610 | D8: 70000 | E8: 0.035359208 | F8: 0.93620324 | G8: 79.666667
A9: Grand Total | B9: 13225810 | C9: 12373820 | D9: 361506 | E9: 0.029820767 | F9: 0.93456499 | G9: 511.66667
A14: Data Accuracy
A15: Check whether closing stocks = openingstocks +(produced-rejectd) -dispatched
A16: {=SUMPRODUCT(Data!AE2:AE2001 <> Data!AB2:AB2001 + Data!R2:R2001 -Data!S2:S2001 -Data!AD2:AD2001)} -> 0
A18: Check whether rejected > produced
A19: {=SUMPRODUCT(--(Data!S2:S2001 > Data!R2:R2001))} -> 0
A21: Check whether present > planned manpower
A22: {=SUMPRODUCT(--(Data!P2:P2001 >Data!O2:O2001) )} -> 0
A24: Check whether there exist duplicate record_id
A25: {=SUMPRODUCT(--(COUNTIF(Data!A2:A2001,Data!A2:A2001)>1))} -> 0
A27: Check whether there exist duplicate batch_id
A28: {=SUMPRODUCT(--(COUNTIF(Data!L2:L2001,Data!L2:L2001)>1))} -> 0
A32: Which line shows a change in rejection % over the six months, and from which month?
A35: Average of Rejection% | C35: Line_ID
A36: Month_No. | B36: Month | C36: L1 | D36: L2 | E36: L3 | F36: L4 | G36: Grand Total
A37: 4 | B37: Apr-2026 | C37: 0.023400663 | D37: 0.023874114 | E37: 0.024054504 | F37: 0.024410945 | G37: 0.02393705
A38: 4 Total | C38: 0.023400663 | D38: 0.023874114 | E38: 0.024054504 | F38: 0.024410945 | G38: 0.02393705
A39: 5 | B39: May-2026 | C39: 0.025455748 | D39: 0.025900516 | E39: 0.025575153 | F39: 0.025977222 | G39: 0.025725994
A40: 5 Total | C40: 0.025455748 | D40: 0.025900516 | E40: 0.025575153 | F40: 0.025977222 | G40: 0.025725994
A41: 6 | B41: Jun-2026 | C41: 0.023903497 | D41: 0.025052131 | E41: 0.025014339 | F41: 0.025419763 | G41: 0.024853198
A42: 6 Total | C42: 0.023903497 | D42: 0.025052131 | E42: 0.025014339 | F42: 0.025419763 | G42: 0.024853198
A43: 7 | B43: Jul-2026 | C43: 0.025225825 | D43: 0.063972517 | E43: 0.024982457 | F43: 0.024096897 | G43: 0.03471363
A44: 7 Total | C44: 0.025225825 | D44: 0.063972517 | E44: 0.024982457 | F44: 0.024096897 | G44: 0.03471363
A45: 8 | B45: Aug-2026 | C45: 0.024074218 | D45: 0.06303566 | E45: 0.024635578 | F45: 0.024757979 | G45: 0.034210622
A46: 8 Total | C46: 0.024074218 | D46: 0.06303566 | E46: 0.024635578 | F46: 0.024757979 | G46: 0.034210622
A47: 9 | B47: Sep-2026 | C47: 0.023887273 | D47: 0.067346625 | E47: 0.025655801 | F47: 0.023976176 | G47: 0.035359208
A48: 9 Total | C48: 0.023887273 | D48: 0.067346625 | E48: 0.025655801 | F48: 0.023976176 | G48: 0.035359208
A49: Grand Total | C49: 0.024340287 | D49: 0.045090487 | E49: 0.024987626 | F49: 0.02478214 | G49: 0.029820767
A73: Other lines have approximately same % of rejection, but rejection % of "Mouthwash Bottling" has increased from 2.5% to 6.73 % from july to september.
A76: Which shift has the highest rejection %? Is that the whole story?
A78: Shift | B78: Average of Rejection%
A79: A | B79: 0.028173329
...

Sheet KPI
A1: Rejection %
A2: 0.029820767 | C2: =SUM(Data!S2:S2001)/SUM(Data!R2:R2001) -> 0.029215392 | E2: Rejection% of L2
E3: =SUMIFS(Data!S2:S2001,Data!G2:G2001, "=L2",Data!D2:D2001,"<10", Data!D2:D2001,">6")/SUMIFS(Data!R2:R2001,Data!G2:G2001, "=L2",Data!D2:D2001,"<10",Data!D2:D2001,">6") -> 0.065029946
A4: Plan Achievement %
A5: 0.93456499 | C5: =A5 -> 0.93456499
A7: Line_ID | B7: Month
A8: L2 | B8: Aug-2026
B9: Jul-2026
B10: Sep-2026
A11: L2 Total
A12: Grand Total
A16: {=SUM(IF(Data!N2:N2001 ="Packright Industries",Data!AA2:AA2001,0)) -SUM(IF(Data!N2:N2001 = "PackRight Industries",Data!R2:R2001 *Data!Z2:Z2001,0))*0.025} -> 3180159.8 | B16: rejection loss amount | E16: Normal Loss Amount | F16: Excess Loss Amount | G16: Total Loss Amount
E17: {=SUMPRODUCT(--(Data!N2:N2001="Packright Industries"),Data!R2:R2001 *Data!Z2:Z2001)*0.025} -> 1010847.2 | F17: {=SUM(IF(Data!N2:N2001 ="Packright Industries",Data!AA2:AA2001,0)) -SUM(IF(Data!N2:N2001 = "PackRight Industries",Data!R2:R2001 *Data!Z2:Z2001,0))*0.025} -> 3180159.8 | G17: =SUM(F17,E17) -> 4191007
A20: Zero stocks runs
A21: =COUNTIF(Data!AE2:AE2001,"=0") -> 20
A24: Average of Rejection% | D24: Packaging_Supplier
A25: Line_ID | B25: Month_No. | C25: Month | D25: Delhi Poly Pack | E25: PackRight Industries | F25: Sunrise Packaging | G25: Grand Total
A26: L2 | B26: 4 | C26: Apr-2026 | D26: 0.023153439 | F26: 0.02452775 | G26: 0.023874114
B27: 4 Total | D27: 0.023153439 | F27: 0.02452775 | G27: 0.023874114
B28: 5 | C28: May-2026 | D28: 0.024570151 | F28: 0.026815142 | G28: 0.025900516
B29: 5 Total | D29: 0.024570151 | F29: 0.026815142 | G29: 0.025900516
B30: 6 | C30: Jun-2026 | D30: 0.024642162 | F30: 0.025559198 | G30: 0.025052131
B31: 6 Total | D31: 0.024642162 | F31: 0.025559198 | G31: 0.025052131
B32: 7 | C32: Jul-2026 | D32: 0.023067955 | E32: 0.10322195 | F32: 0.02484135 | G32: 0.063972517
B33: 7 Total | D33: 0.023067955 | E33: 0.10322195 | F33: 0.02484135 | G33: 0.063972517
B34: 8 | C34: Aug-2026 | D34: 0.02490907 | E34: 0.10240048 | F34: 0.022828847 | G34: 0.06303566
B35: 8 Total | D35: 0.02490907 | E35: 0.10240048 | F35: 0.022828847 | G35: 0.06303566
B36: 9 | C36: Sep-2026 | D36: 0.025659549 | E36: 0.10580394 | F36: 0.026350466 | G36: 0.067346625
B37: 9 Total | D37: 0.025659549 | E37: 0.10580394 | F37: 0.026350466 | G37: 0.067346625
A38: L2 Total | D38: 0.024228314 | E38: 0.10381516 | F38: 0.025301794 | G38: 0.045090487
A39: Grand Total | D39: 0.024228314 | E39: 0.10381516 | F39: 0.025301794 | G39: 0.045090487
A50: Line_ID | B50: Month_No. | C50: Month | D50: Average of Closing_FG_Stock | E50: Average of Reorder_Level
A51: L2 | B51: 4 | C51: Apr-2026 | D51: 18938.768 | E51: 8963.4146
B52: 4 Total | D52: 18938.768 | E52: 8963.4146
B53: 5 | C53: May-2026 | D53: 21451.123 | E53: 9009.2593
B54: 5 Total | D54: 21451.123 | E54: 9009.2593
B55: 6 | C55: Jun-2026 | D55: 24034.882 | E55: 8876.4706
B56: 6 Total | D56: 24034.882 | E56: 8876.4706
B57: 7 | C57: Jul-2026 | D57: 19701.483 | E57: 8758.6207
B58: 7 Total | D58: 19701.483 | E58: 8758.6207
...

Sheet Dashboard
A5: =KPI!C5 -> 0.93456499 | F5: =KPI!C2 -> 0.029215392 | K5: =KPI!E3 -> 0.065029946 | P5: =KPI!A16 -> 3180159.8 | U5: =KPI!A21 -> 20
